Workbook

Sheet Consol List ESOP Given
H1: Can Convert
D2: FY2022 | E2: FY2023 | F2: FY2024 | G2: FY2025 | H2: FY2026 | I2: FY2027
C3: Total Shares | D3: 30000000 | E3: 30000000 | F3: 32432432 | G3: =F3 -> 32432432
B4: 0.2 | C4: Total Cap | D4: =$B$4*D3 -> 6000000 | E4: =$B$4*E3 -> 6000000 | F4: =$B$4*F3 -> 6486486.4 | G4: =$B$4*G3 -> 6486486.4 | H4: =$B$4*H3 -> 0 | I4: =$B$4*I3 -> 0
C5: Yearly Cap | D5: =D4/5 -> 1200000 | E5: =E4/5 -> 1200000 | F5: =F4/5 -> 1297297.3 | G5: =G4/5 -> 1297297.3 | H5: =H4/5 -> 0 | I5: =I4/5 -> 0
C7: Total ESOP Given | D7: 461000 | E7: =F5*E8 -> 648648.64 | F7: =G5*F8 -> 648648.64 | G7: =H5*G8 -> 0
C8: % to yearly Cap | D8: =D7/E5 -> 0.38416667 | E8: 0.5 | F8: 0.5 | G8: 0.5
D9: FY 2022 | E9: FY 2023 | F9: FY 2024 | G9: FY 2025
C10: Total Outstanding Shares | H10: =G3 -> 32432432
C11: Total ESOP given | D11: =sum(D15:D200) -> 366000 | E11: =sum(E15:E200) -> 0 | F11: =sum(F15:F200) -> 1200000 | G11: =sum(G15:G200) -> 535300 | H11: =sum(D11:G11) -> 2101300
H12: =H11/H10 -> 0.064790084
B13: Issued Date | D13: 15/7/22 | F13: 31/7/24 | G13: 45879
B14: Employee Pool | C14: Name | D14: FY 2022 | E14: FY 2023 | F14: FY 2024 | G14: FY 2025 | H14: Total | J14: EMAIL
B15: 1 | C15: Tok Meiting | D15: 60000 | F15: 71595.331 | G15: 40400 | H15: =sum(D15:G15) -> 171995.33 | J15: meiting@elitez.asia
B16: 2 | C16: Li Qian | D16: 60000 | F16: 71595.331 | G16: 40400 | H16: =sum(D16:G16) -> 171995.33 | J16: liqian@elitez.asia
B17: 3 | C17: Eevann Seah | D17: 35000 | F17: 66926.07 | G17: 39200 | H17: =sum(D17:G17) -> 141126.07 | J17: eevann.seah@elitez.asia
B18: 4 | C18: Wang Jiemin (Jack) | D18: 40000 | F18: 69260.7 | G18: 42700 | H18: =sum(D18:G18) -> 151960.7 | J18: jack.wang@elitez.asia
B19: 5 | C19: Daryl Toh | F19: 44357.977 | H19: =sum(D19:G19) -> 44357.977
B20: 6 | C20: Sharon Lau Jie Joo | D20: 40000 | F20: 66926.07 | G20: 9700 | H20: =sum(D20:G20) -> 116626.07 | J20: sharon.lau@elitez.asia
B21: 7 | C21: Yeoh Ser How | D21: 26000 | F21: 52140.078 | G21: 9700 | H21: =sum(D21:G21) -> 87840.078 | J21: serhow.yeoh@elitez.asia
B22: 8 | C22: Samion Ong
B23: 9 | C23: Chan Wai Seng, Nicholas | D23: 25000 | F23: 40466.926 | G23: 18500 | H23: =sum(D23:G23) -> 83966.926 | J23: nicholas.chan@elitez.asia
B24: 10 | C24: Philip Leong
B25: 11 | C25: Asmond Soh
B26: 12 | C26: Damien Tan Han Kiap | D26: 20000 | F26: 45914.397 | G26: 17100 | H26: =sum(D26:G26) -> 83014.397 | J26: damien.tan@elitez.asia
B27: 13 | C27: Chen Ting | D27: 20000 | F27: 48249.027 | G27: 13700 | H27: =sum(D27:G27) -> 81949.027 | J27: chenting@elitez.asia
B28: 14 | C28: Andy Lim Wen Jie | D28: 20000 | F28: 40466.926 | G28: 15000 | H28: =sum(D28:G28) -> 75466.926 | J28: andy@elitez.asia
B29: 15 | C29: Aiydon Li Yi Xuan | D29: 20000 | F29: 55252.918 | G29: 13700 | H29: =sum(D29:G29) -> 88952.918 | J29: aiydon@elitez.asia
B30: 16 | C30: Wong Siew Hua | D30: 0 | F30: 45914.397 | G30: 28700 | H30: =sum(D30:G30) -> 74614.397 | J30: siewhua.wong@elitez.asia
B31: 17 | C31: Kan Siew Weng | D31: 0 | F31: 45914.397 | G31: 15000 | H31: =sum(D31:G31) -> 60914.397 | J31: siewweng.kan@elitez.asia
B32: 18 | C32: How Hee Chek (Jaysen) | D32: 0 | F32: 36575.875 | G32: 15000 | H32: =sum(D32:G32) -> 51575.875 | J32: jaysen@dhc.com.sg
B33: 19 | C33: Lim Runting | D33: 0 | F33: 41245.136 | G33: 11300 | H33: =sum(D33:G33) -> 52545.136 | J33: runting@dhc.com.sg
B34: 20 | C34: Ho Si Cong | D34: 0 | F34: 40466.926 | G34: 8200 | H34: =sum(D34:G34) -> 48666.926 | J34: sicong@dhc.com.sg
B35: 21 | C35: Tiong Kai Yuen, Noreen | D35: 0 | F35: 29571.984 | G35: 7300 | H35: =sum(D35:G35) -> 36871.984 | J35: noreen@dhc.com.sg
B36: 22 | C36: Tan Hui Qing | D36: 0 | F36: 41245.136 | G36: 23300 | H36: =sum(D36:G36) -> 64545.136 | J36: huiqing@dhc.com.sg
B37: 23 | C37: Kenneth Koh | D37: 0 | F37: 45914.397 | G37: 2300 | H37: =sum(D37:G37) -> 48214.397 | J37: kenneth.koh@elitez.asia
... B46: 32 | C46: Chan Huan Zhang Adrian | D46: 0 | F46: 0 | G46: 10200 | H46: =sum(D46:G46) -> 10200 | J46: adrian.chan@elitez.asia

Sheet DHC
C5: Employee | D5: Years in Company | E5: Current Year Performance | F5: Leadership Potential | G5: Total Score (Raw) | H5: Entity | I5: Remarks
B6: Example | C6: Rongjie | D6: 4 | E6: 4 | F6: 5 | G6: 4.25 | H6: Elitez Pte Ltd | I6: Example
B7: 1 | C7: Jaysen | E7: 3 | F7: 0 | G7: 2.4 | H7: DHC Pte Ltd | J7: 43476
B8: 2 | C8: Runting | E8: 3 | F8: 0 | G8: 3.3 | H8: DHC Pte Ltd | J8: 18/11/2013
B9: 3 | C9: Si Cong | E9: 3 | F9: 3 | G9: 3.15 | H9: DHC Pte Ltd | J9: 16/04/2019
B10: 4 | C10: Noreen | E10: 3 | F10: 0 | G10: 2.7 | H10: DHC Pte Ltd | J10: 20/03/2017
B11: 5 | C11: Huiqing | E11: 3 | F11: 3 | G11: 3.75 | H11: DHC Pte Ltd | J11: 42038

Sheet 2024- Working
F1: Weightage
C3: Factor 1 | D3: Years in Company | F3: 0.15
C4: Factor 2 | D4: Current Year Performance | F4: 0.6
C5: Factor 3 | D5: Leadership Potential | F5: 0.25 | N5: Total Shares to be given (20%) | P5: 6000000
D7: =SUM(D11:D22) -> 401000 | E7: =D7/D8 -> 0.013366667 | H7: Ending dates | I7: 45413
D8: 30000000 | E8: =D7/P5 -> 0.066833333 | I8: Scale of | J8: 0 to 5 | M8: Total | O8: Total Shares for EGPL 2024
I9: Weightage | J9: 0.15 | K9: 0.6 | L9: 0.25 | M9: =sum(M11:M34) -> 77.1 | O9: 1200000
B10: Employee Pool | C10: Name | D10: 2022 15 July 2022 (5 Years Vest) | E10: Formatted Grading | F10: Grading for FY 2024 | G10: Formatted Joined Date | H10: Joined Date | I10: Years in Company(as of 1 May 2024) | J10: Factor 1 | K10: Factor 2 | L10: Factor 3 | M10: Total Score | N10: Percentage | O10: ESOP Given
A11: HR | B11: 1 | C11: Tok Meiting | D11: 60000 | E11: 5 | F11: A | G11: 42058 | H11: 42058 | I11: =days(G11,$I$7)/-365 -> 9.1917808 | J11: =vlookup(I11,'Table for Factors'!$C$30:$D$35,2,true) -> 4 | K11: =vlookup(E11,'Table for Factors'!$C$38:$D$43,2,false) -> 5 | L11: 4 | M11: =SUMPRODUCT(J11:L11,$J$9:$L$9) -> 4.6 | N11: =M11/$M$9 -> 0.059662776 | O11: =N11*$O$9 -> 71595.331
A12: FIN | B12: 2 | C12: Li Qian | D12: 60000 | E12: 5 | F12: A+ | G12: 42060 | H12: 42060 | I12: =days(G12,$I$7)/-365 -> 9.1863014 | J12: =vlookup(I12,'Table for Factors'!$C$30:$D$35,2,true) -> 4 | K12: =vlookup(E12,'Table for Factors'!$C$38:$D$43,2,false) -> 5 | L12: 4 | M12: =SUMPRODUCT(J12:L12,$J$9:$L$9) -> 4.6 | N12: =M12/$M$9 -> 0.059662776 | O12: =N12*$O$9 -> 71595.331
A13: SALES | B13: 3 | C13: Eevann Seah | D13: 35000 | E13: 5 | F13: A | G13: 43283 | H13: 43283 | I13: =days(G13,$I$7)/-365 -> 5.8356164 | J13: =vlookup(I13,'Table for Factors'!$C$30:$D$35,2,true) -> 2 | K13: =vlookup(E13,'Table for Factors'!$C$38:$D$43,2,false) -> 5 | L13: 4 | M13: =SUMPRODUCT(J13:L13,$J$9:$L$9) -> 4.3 | N13: =M13/$M$9 -> 0.055771725 | O13: =N13*$O$9 -> 66926.07
A14: SALES | B14: 4 | C14: Jack Wang | D14: 40000 | E14: 5 | F14: A | G14: 42681 | H14: 42681 | I14: =days(G14,$I$7)/-365 -> 7.4849315 | J14: =vlookup(I14,'Table for Factors'!$C$30:$D$35,2,true) -> 3 | K14: =vlookup(E14,'Table for Factors'!$C$38:$D$43,2,false) -> 5 | L14: 4 | M14: =SUMPRODUCT(J14:L14,$J$9:$L$9) -> 4.45 | N14: =M14/$M$9 -> 0.05771725 | O14: =N14*$O$9 -> 69260.7
A15: OPS | B15: 5 | C15: Daryl Toh | D15: 35000 | E15: 4.5 | F15: B | G15: 42961 | H15: 42961 | I15: =days(G15,$I$7)/-365 -> 6.7178082 | J15: =vlookup(I15,'Table for Factors'!$C$30:$D$35,2,true) -> 2 | K15: =vlookup(E15,'Table for Factors'!$C$38:$D$43,2,false) -> 3 | L15: 3 | M15: =SUMPRODUCT(J15:L15,$J$9:$L$9) -> 2.85 | N15: =M15/$M$9 -> 0.036964981 | O15: =N15*$O$9 -> 44357.977
A16: SALES | B16: 6 | C16: Sharon Lau | D16: 40000 | E16: 5 | F16: A | G16: 42979 | H16: 42979 | I16: =days(G16,$I$7)/-365 -> 6.6684932 | J16: =vlookup(I16,'Table for Factors'!$C$30:$D$35,2,true) -> 2 | K16: =vlookup(E16,'Table for Factors'!$C$38:$D$43,2,false) -> 5 | L16: 4 | M16: =SUMPRODUCT(J16:L16,$J$9:$L$9) -> 4.3 | N16: =M16/$M$9 -> 0.055771725 | O16: =N16*$O$9 -> 66926.07
A17: OPS | B17: 7 | C17: Yeoh Ser How | D17: 26000 | E17: 4.75 | F17: B+ | G17: 42626 | H17: 42626 | I17: =days(G17,$I$7)/-365 -> 7.6356164 | J17: =vlookup(I17,'Table for Factors'!$C$30:$D$35,2,true) -> 3 | K17: =vlookup(E17,'Table for Factors'!$C$38:$D$43,2,false) -> 4 | L17: 2 | M17: =SUMPRODUCT(J17:L17,$J$9:$L$9) -> 3.35 | N17: =M17/$M$9 -> 0.043450065 | O17: =N17*$O$9 -> 52140.078
A18: SALES | B18: 8 | C18: Nicholas Chan | D18: 25000 | E18: 4.5 | F18: B | G18: 43769 | H18: 43769 | I18: =days(G18,$I$7)/-365 -> 4.5041096 | J18: =vlookup(I18,'Table for Factors'!$C$30:$D$35,2,true) -> 2 | K18: =vlookup(E18,'Table for Factors'!$C$38:$D$43,2,false) -> 3 | L18: 2 | M18: =SUMPRODUCT(J18:L18,$J$9:$L$9) -> 2.6 | N18: =M18/$M$9 -> 0.033722438 | O18: =N18*$O$9 -> 40466.926
A19: SALES | B19: 9 | C19: Damien Tan | D19: 20000 | E19: 4.75 | F19: B+ | G19: 43009 | H19: 43009 | I19: =days(G19,$I$7)/-365 -> 6.5863014 | J19: =vlookup(I19,'Table for Factors'!$C$30:$D$35,2,true) -> 2 | K19: =vlookup(E19,'Table for Factors'!$C$38:$D$43,2,false) -> 4 | L19: 1 | M19: =SUMPRODUCT(J19:L19,$J$9:$L$9) -> 2.95 | N19: =M19/$M$9 -> 0.038261997 | O19: =N19*$O$9 -> 45914.397
A20: FIN | B20: 10 | C20: Chen Ting | D20: 20000 | E20: 4.75 | F20: B+ | G20: 42499 | H20: 42499 | I20: =days(G20,$I$7)/-365 -> 7.9835616 | J20: =vlookup(I20,'Table for Factors'!$C$30:$D$35,2,true) -> 3 | K20: =vlookup(E20,'Table for Factors'!$C$38:$D$43,2,false) -> 4 | L20: 1 | M20: =SUMPRODUCT(J20:L20,$J$9:$L$9) -> 3.1 | N20: =M20/$M$9 -> 0.040207523 | O20: =N20*$O$9 -> 48249.027
A21: ESG | B21: 11 | C21: Andy Lim | D21: 20000 | E21: 4.5 | F21: B | G21: 43339 | H21: 43339 | I21: =days(G21,$I$7)/-365 -> 5.6821918 | J21: =vlookup(I21,'Table for Factors'!$C$30:$D$35,2,true) -> 2 | K21: =vlookup(E21,'Table for Factors'!$C$38:$D$43,2,false) -> 3 | L21: 2 | M21: =SUMPRODUCT(J21:L21,$J$9:$L$9) -> 2.6 | N21: =M21/$M$9 -> 0.033722438 | O21: =N21*$O$9 -> 40466.926
A22: HR | B22: 12 | C22: Aiydon | D22: 20000 | E22: 5 | F22: A | G22: 43011 | H22: 43011 | I22: =days(G22,$I$7)/-365 -> 6.5808219 | J22: =vlookup(I22,'Table for Factors'!$C$30:$D$35,2,true) -> 2 | K22: =vlookup(E22,'Table for Factors'!$C$38:$D$43,2,false) -> 5 | L22: 1 | M22: =SUMPRODUCT(J22:L22,$J$9:$L$9) -> 3.55 | N22: =M22/$M$9 -> 0.046044099 | O22: =N22*$O$9 -> 55252.918
A23: FIN | B23: 13 | C23: Siew Hua | E23: 4.75 | F23: B+ | G23: 43556 | H23: 43556 | I23: =days(G23,$I$7)/-365 -> 5.0876712 | J23: =vlookup(I23,'Table for Factors'!$C$30:$D$35,2,true) -> 2 | K23: =vlookup(E23,'Table for Factors'!$C$38:$D$43,2,false) -> 4 | L23: 1 | M23: =SUMPRODUCT(J23:L23,$J$9:$L$9) -> 2.95 | N23: =M23/$M$9 -> 0.038261997 | O23: =N23*$O$9 -> 45914.397
A24: FIN | B24: 14 | C24: Siew Weng | E24: 4.75 | F24: B+ | G24: 43578 | H24: 43578 | I24: =days(G24,$I$7)/-365 -> 5.0273973 | J24: =vlookup(I24,'Table for Factors'!$C$30:$D$35,2,true) -> 2 | K24: =vlookup(E24,'Table for Factors'!$C$38:$D$43,2,false) -> 4 | L24: 1 | M24: =SUMPRODUCT(J24:L24,$J$9:$L$9) -> 2.95 | N24: =M24/$M$9 -> 0.038261997 | O24: =N24*$O$9 -> 45914.397
A25: DHC | B25: 15 | C25: Jaysen How | E25: 4.5 | G25: 43770 | H25: 43770 | I25: =days(G25,$I$7)/-365 -> 4.5013699 | J25: =vlookup(I25,'Table for Factors'!$C$30:$D$35,2,true) -> 2 | K25: =vlookup(E25,'Table for Factors'!$C$38:$D$43,2,false) -> 3 | L25: 1 | M25: =SUMPRODUCT(J25:L25,$J$9:$L$9) -> 2.35 | N25: =M25/$M$9 -> 0.030479896 | O25: =N25*$O$9 -> 36575.875
A26: DHC | B26: 16 | C26: Lim Runting | E26: 4.5 | G26: 41596 | H26: 41596 | I26: =days(G26,$I$7)/-365 -> 10.457534 | J26: =vlookup(I26,'Table for Factors'!$C$30:$D$35,2,true) -> 4 | K26: =vlookup(E26,'Table for Factors'!$C$38:$D$43,2,false) -> 3 | L26: 1 | M26: =SUMPRODUCT(J26:L26,$J$9:$L$9) -> 2.65 | N26: =M26/$M$9 -> 0.034370947 | O26: =N26*$O$9 -> 41245.136
A27: DHC | B27: 17 | C27: Ho Si Cong | E27: 4.5 | G27: 43570 | H27: 43570 | I27: =days(G27,$I$7)/-365 -> 5.0493151 | J27: =vlookup(I27,'Table for Factors'!$C$30:$D$35,2,true) -> 2 | K27: =vlookup(E27,'Table for Factors'!$C$38:$D$43,2,false) -> 3 | L27: 2 | M27: =SUMPRODUCT(J27:L27,$J$9:$L$9) -> 2.6 | N27: =M27/$M$9 -> 0.033722438 | O27: =N27*$O$9 -> 40466.926
A28: DHC | B28: 18 | C28: Noreen Tiong | E28: 4 | G28: 42814 | H28: 42814 | I28: =days(G28,$I$7)/-365 -> 7.1205479 | J28: =vlookup(I28,'Table for Factors'!$C$30:$D$35,2,true) -> 3 | K28: =vlookup(E28,'Table for Factors'!$C$38:$D$43,2,false) -> 2 | L28: 1 | M28: =SUMPRODUCT(J28:L28,$J$9:$L$9) -> 1.9 | N28: =M28/$M$9 -> 0.02464332 | O28: =N28*$O$9 -> 29571.984
A29: DHC | B29: 19 | C29: Tan Huiqing | E29: 4.5 | G29: 42065 | H29: 42065 | I29: =days(G29,$I$7)/-365 -> 9.1726027 | J29: =vlookup(I29,'Table for Factors'!$C$30:$D$35,2,true) -> 4 | K29: =vlookup(E29,'Table for Factors'!$C$38:$D$43,2,false) -> 3 | L29: 1 | M29: =SUMPRODUCT(J29:L29,$J$9:$L$9) -> 2.65 | N29: =M29/$M$9 -> 0.034370947 | O29: =N29*$O$9 -> 41245.136
A30: OPS | B30: 20 | C30: Kenneth Koh | E30: 4.75 | F30: B+ | G30: 43600 | H30: 43600 | I30: =days(G30,$I$7)/-365 -> 4.9671233 | J30: =vlookup(I30,'Table for Factors'!$C$30:$D$35,2,true) -> 2 | K30: =vlookup(E30,'Table for Factors'!$C$38:$D$43,2,false) -> 4 | L30: 1 | M30: =SUMPRODUCT(J30:L30,$J$9:$L$9) -> 2.95 | N30: =M30/$M$9 -> 0.038261997 | O30: =N30*$O$9 -> 45914.397
A31: SALES | B31: 21 | C31: Ian Heng | E31: 5 | F31: A | G31: 43717 | H31: 43717 | I31: =days(G31,$I$7)/-365 -> 4.6465753 | J31: =vlookup(I31,'Table for Factors'!$C$30:$D$35,2,true) -> 2 | K31: =vlookup(E31,'Table for Factors'!$C$38:$D$43,2,false) -> 5 | L31: 3 | M31: =SUMPRODUCT(J31:L31,$J$9:$L$9) -> 4.05 | N31: =M31/$M$9 -> 0.052529183 | O31: =N31*$O$9 -> 63035.019
A32: SALES | B32: 22 | C32: Penny Tsai | E32: 4.5 | F32: B | G32: 43773 | H32: 43773 | I32: =days(G32,$I$7)/-365 -> 4.4931507 | J32: =vlookup(I32,'Table for Factors'!$C$30:$D$35,2,true) -> 2 | K32: =vlookup(E32,'Table for Factors'!$C$38:$D$43,2,false) -> 3 | L32: 1 | M32: =SUMPRODUCT(J32:L32,$J$9:$L$9) -> 2.35 | N32: =M32/$M$9 -> 0.030479896 | O32: =N32*$O$9 -> 36575.875 | AC32: Factor 1: Years | AF32: Factor 2 :Current Year Performance | AI32: Factor 3 :Current Year Performance
A33: SALES | B33: 23 | C33: Jorena Tan | E33: 5 | F33: A | G33: 44088 | H33: 44088 | I33: =days(G33,$I$7)/-365 -> 3.630137 | J33: =vlookup(I33,'Table for Factors'!$C$30:$D$35,2,true) -> 1 | K33: =vlookup(E33,'Table for Factors'!$C$38:$D$43,2,false) -> 5 | L33: 2 | M33: =SUMPRODUCT(J33:L33,$J$9:$L$9) -> 3.65 | N33: =M33/$M$9 -> 0.047341115 | O33: =N33*$O$9 -> 56809.339 | AC33: Points | AD33: Years | AF33: Points | AG33: Scoring | AI33: Points | AJ33: Potential
A34: SALES | B34: 25 | C34: Melissa Tan | E34: 4.75 | F34: B+ | G34: 44308 | H34: 44308 | I34: =days(G34,$I$7)/-365 -> 3.0273973 | J34: =vlookup(I34,'Table for Factors'!$C$30:$D$35,2,true) -> 1 | K34: =vlookup(E34,'Table for Factors'!$C$38:$D$43,2,false) -> 4 | L34: 1 | M34: =SUMPRODUCT(J34:L34,$J$9:$L$9) -> 2.8 | N34: =M34/$M$9 -> 0.036316472 | O34: =N34*$O$9 -> 43579.767 | AC34: 1 | AD34: 3 | AF34: 1 | AG34: 3.5 | AI34: 1
AC35: 2 | AD35: 5 | AF35: 2 | AG35: 4 | AI35: 2
L36: Total | M36: =sum(M11:M34) -> 77.1 | N36: =sum(N11:N34) -> 1 | O36: =sum(O11:O34) -> 1200000
P38: Total
F42: Ho Si Cong 1 Mar 2021 - Actual 15/04/2019
A43: SALES | B43: 24 | C43: Hailey Yang | E43: 5 | F43: A | G43: 44410 | H43: 44410 | I43: =days(G43,$I$7)/-365 -> 2.7479452 | J43: 1 | K43: =vlookup(E43,'Table for Factors'!$C$38:$D$43,2,false) -> 5 | L43: 2 | M43: =SUMPRODUCT(J43:L43,$J$9:$L$9) -> 3.65 | N43: =M43/$M$9 -> 0.047341115
A44: SALES | B44: 26 | C44: Densil Tan | E44: 4.75 | F44: B+ | G44: 44652 | H44: 44652 | I44: =days(G44,$I$7)/-365 -> 2.0849315 | J44: 1 | K44: =vlookup(E44,'Table for Factors'!$C$38:$D$43,2,false) -> 4 | L44: 1 | M44: =SUMPRODUCT(J44:L44,$J$9:$L$9) -> 2.8 | N44: =M44/$M$9 -> 0.036316472 | AC44: 3 | AD44: 7 | AF44: 3 | AG44: 4.5 | AI44: 3
A45: LEFT | B45: 8 | C45: Samion Ong | D45: 20000 | F45: Jorena Tan 14 Sep 2020 - correct
A46: LEFT | B46: 10 | C46: Philip Leong | D46: 20000 | F46: Hailey Yang 2 Aug 2021 - correct
...

Sheet Final 2024
J1: Weightage
C3: Factor 1 | H3: Years in Company | J3: 0.15
C4: Factor 2 | H4: Current Year Performance | J4: 0.6
C5: Factor 3 | H5: Leadership Potential | J5: 0.25 | R5: Total Shares to be given (20%) | T5: 6000000
H7: =SUM(H11:H22) -> 401000 | I7: =H7/H8 -> 0.013366667 | L7: Ending dates | M7: 45413
H8: 30000000 | I8: =H7/T5 -> 0.066833333 | M8: Scale of | N8: 0 to 5 | Q8: Total | S8: Total Shares for EGPL 2024
M9: Weightage | N9: 0.15 | O9: 0.6 | P9: 0.25 | Q9: =sum(Q11:Q34) -> 77.1 | S9: 1200000
B10: Employee Pool | C10: Name | D10: Job Title | E10: Address | F10: Nationality | G10: Identity No | H10: 2022 15 July 2022 (5 Years Vest) | I10: Formatted Grading | J10: Grading for FY 2024 | K10: Formatted Joined Date | L10: Joined Date | M10: Years in Company(as of 1 May 2024) | N10: Factor 1 | O10: Factor 2 | P10: Factor 3 | Q10: Total Score | R10: Percentage | S10: 2024 ESOP Given
A11: HR | B11: 1 | C11: Tok Meiting | D11: HR Manager | E11: 653C Punggol Drive #13-80 S (823653) | F11: Singaporean | G11: S9408267F | H11: 60000 | I11: 5 | J11: A | K11: 42058 | L11: 42058 | M11: =days(K11,$M$7)/-365 -> 9.1917808 | N11: =vlookup(M11,'Table for Factors'!$C$30:$D$35,2,true) -> 4 | O11: =vlookup(I11,'Table for Factors'!$C$38:$D$43,2,false) -> 5 | P11: 4 | Q11: =SUMPRODUCT(N11:P11,$N$9:$P$9) -> 4.6 | R11: =Q11/$Q$9 -> 0.059662776 | S11: =R11*$S$9 -> 71595.331 | U11: =Q11/5*60000 -> 55200
A12: FIN | B12: 2 | C12: Li Qian | D12: Senior Finance Manager | E12: 129 Ang Mo Kio Avenue 3 #11-1549 S(560129) | F12: Singaporean | G12: S9077139F | H12: 60000 | I12: 5 | J12: A+ | K12: 42060 | L12: 42060 | M12: =days(K12,$M$7)/-365 -> 9.1863014 | N12: =vlookup(M12,'Table for Factors'!$C$30:$D$35,2,true) -> 4 | O12: =vlookup(I12,'Table for Factors'!$C$38:$D$43,2,false) -> 5 | P12: 4 | Q12: =SUMPRODUCT(N12:P12,$N$9:$P$9) -> 4.6 | R12: =Q12/$Q$9 -> 0.059662776 | S12: =R12*$S$9 -> 71595.331 | U12: =Q12/5*60000 -> 55200
A13: SALES | B13: 3 | C13: Eevann Seah | D13: Senior Manager | E13: 128A Canberra Street #11-508 S(751128) | F13: Singaporean | G13: S9038620D | H13: 35000 | I13: 5 | J13: A | K13: 43283 | L13: 43283 | M13: =days(K13,$M$7)/-365 -> 5.8356164 | N13: =vlookup(M13,'Table for Factors'!$C$30:$D$35,2,true) -> 2 | O13: =vlookup(I13,'Table for Factors'!$C$38:$D$43,2,false) -> 5 | P13: 4 | Q13: =SUMPRODUCT(N13:P13,$N$9:$P$9) -> 4.3 | R13: =Q13/$Q$9 -> 0.055771725 | S13: =R13*$S$9 -> 66926.07 | U13: =Q13/5*60000 -> 51600
A14: SALES | B14: 4 | C14: Wang Jiemin (Jack) | D14: Senior Manager | E14: 522B Tampines Central 7 #03-15 S(522522) | F14: Singaporean | G14: S8818978G | H14: 40000 | I14: 5 | J14: A | K14: 42681 | L14: 42681 | M14: =days(K14,$M$7)/-365 -> 7.4849315 | N14: =vlookup(M14,'Table for Factors'!$C$30:$D$35,2,true) -> 3 | O14: =vlookup(I14,'Table for Factors'!$C$38:$D$43,2,false) -> 5 | P14: 4 | Q14: =SUMPRODUCT(N14:P14,$N$9:$P$9) -> 4.45 | R14: =Q14/$Q$9 -> 0.05771725 | S14: =R14*$S$9 -> 69260.7 | U14: =Q14/5*60000 -> 53400
A15: OPS | B15: 5 | C15: Toh Hui Leong (Daryl) | D15: Senior Manager | E15: 526 Hougang Avenue 6, #10-149 S(530526) | F15: Singaporean | G15: S9048049I | H15: 35000 | I15: 4.5 | J15: B | K15: 42961 | L15: 42961 | M15: =days(K15,$M$7)/-365 -> 6.7178082 | N15: =vlookup(M15,'Table for Factors'!$C$30:$D$35,2,true) -> 2 | O15: =vlookup(I15,'Table for Factors'!$C$38:$D$43,2,false) -> 3 | P15: 3 | Q15: =SUMPRODUCT(N15:P15,$N$9:$P$9) -> 2.85 | R15: =Q15/$Q$9 -> 0.036964981 | S15: =R15*$S$9 -> 44357.977 | U15: =Q15/5*60000 -> 34200
A16: SALES | B16: 6 | C16: Sharon Lau Jie Joo | D16: Senior Manager | E16: 353B Anchorvale Labe #14-83 S(542353) | F16: Malaysian | G16: S9349763E | H16: 40000 | I16: 5 | J16: A | K16: 42979 | L16: 42979 | M16: =days(K16,$M$7)/-365 -> 6.6684932 | N16: =vlookup(M16,'Table for Factors'!$C$30:$D$35,2,true) -> 2 | O16: =vlookup(I16,'Table for Factors'!$C$38:$D$43,2,false) -> 5 | P16: 4 | Q16: =SUMPRODUCT(N16:P16,$N$9:$P$9) -> 4.3 | R16: =Q16/$Q$9 -> 0.055771725 | S16: =R16*$S$9 -> 66926.07 | U16: =Q16/5*60000 -> 51600
A17: OPS | B17: 7 | C17: Yeoh Ser How | D17: Operations Manager | E17: 432B Northshore Drive #22-862 S(822432) | F17: Singaporean | G17: S8876646F | H17: 26000 | I17: 4.75 | J17: B+ | K17: 42626 | L17: 42626 | M17: =days(K17,$M$7)/-365 -> 7.6356164 | N17: =vlookup(M17,'Table for Factors'!$C$30:$D$35,2,true) -> 3 | O17: =vlookup(I17,'Table for Factors'!$C$38:$D$43,2,false) -> 4 | P17: 2 | Q17: =SUMPRODUCT(N17:P17,$N$9:$P$9) -> 3.35 | R17: =Q17/$Q$9 -> 0.043450065 | S17: =R17*$S$9 -> 52140.078 | U17: =Q17/5*60000 -> 40200
A18: SALES | B18: 8 | C18: Chan Wai Seng, Nicholas | D18: Head of Tenders | E18: 31 Lentor Terrace S(788926) | F18: Singaporean | G18: S9220162G | H18: 25000 | I18: 4.5 | J18: B | K18: 43769 | L18: 43769 | M18: =days(K18,$M$7)/-365 -> 4.5041096 | N18: =vlookup(M18,'Table for Factors'!$C$30:$D$35,2,true) -> 2 | O18: =vlookup(I18,'Table for Factors'!$C$38:$D$43,2,false) -> 3 | P18: 2 | Q18: =SUMPRODUCT(N18:P18,$N$9:$P$9) -> 2.6 | R18: =Q18/$Q$9 -> 0.033722438 | S18: =R18*$S$9 -> 40466.926 | U18: =Q18/5*60000 -> 31200
A19: SALES | B19: 9 | C19: Damien Tan Han Kiap | D19: Business Development Manager | E19: 653C Punggol Drive #13-80 S (823653) | F19: Singaporean | G19: S9405253Z | H19: 20000 | I19: 4.75 | J19: B+ | K19: 43009 | L19: 43009 | M19: =days(K19,$M$7)/-365 -> 6.5863014 | N19: =vlookup(M19,'Table for Factors'!$C$30:$D$35,2,true) -> 2 | O19: =vlookup(I19,'Table for Factors'!$C$38:$D$43,2,false) -> 4 | P19: 1 | Q19: =SUMPRODUCT(N19:P19,$N$9:$P$9) -> 2.95 | R19: =Q19/$Q$9 -> 0.038261997 | S19: =R19*$S$9 -> 45914.397 | U19: =Q19/5*60000 -> 35400
A20: FIN | B20: 10 | C20: Chen Ting | D20: Senior Finance Executive | E20: 45 Bendemeer Road, #06-1439 S(330045) | F20: Chinese | G20: S9374645G | H20: 20000 | I20: 4.75 | J20: B+ | K20: 42499 | L20: 42499 | M20: =days(K20,$M$7)/-365 -> 7.9835616 | N20: =vlookup(M20,'Table for Factors'!$C$30:$D$35,2,true) -> 3 | O20: =vlookup(I20,'Table for Factors'!$C$38:$D$43,2,false) -> 4 | P20: 1 | Q20: =SUMPRODUCT(N20:P20,$N$9:$P$9) -> 3.1 | R20: =Q20/$Q$9 -> 0.040207523 | S20: =R20*$S$9 -> 48249.027 | U20: =Q20/5*60000 -> 37200
A21: ESG | B21: 11 | C21: Andy Lim Wen Jie | D21: Deputy Head, ESG | E21: 121B Edgedale Plains #06-193 S(822121) | F21: Singaporean | G21: S9436300D | H21: 20000 | I21: 4.5 | J21: B | K21: 43339 | L21: 43339 | M21: =days(K21,$M$7)/-365 -> 5.6821918 | N21: =vlookup(M21,'Table for Factors'!$C$30:$D$35,2,true) -> 2 | O21: =vlookup(I21,'Table for Factors'!$C$38:$D$43,2,false) -> 3 | P21: 2 | Q21: =SUMPRODUCT(N21:P21,$N$9:$P$9) -> 2.6 | R21: =Q21/$Q$9 -> 0.033722438 | S21: =R21*$S$9 -> 40466.926 | U21: =Q21/5*60000 -> 31200
A22: HR | B22: 12 | C22: Aiydon Li Yi Xuan | D22: Team Lead | E22: 224B Sumang Lane #13-119 S(822224) | F22: Singaporean | G22: S8781890Z | H22: 20000 | I22: 5 | J22: A | K22: 43011 | L22: 43011 | M22: =days(K22,$M$7)/-365 -> 6.5808219 | N22: =vlookup(M22,'Table for Factors'!$C$30:$D$35,2,true) -> 2 | O22: =vlookup(I22,'Table for Factors'!$C$38:$D$43,2,false) -> 5 | P22: 1 | Q22: =SUMPRODUCT(N22:P22,$N$9:$P$9) -> 3.55 | R22: =Q22/$Q$9 -> 0.046044099 | S22: =R22*$S$9 -> 55252.918 | U22: =Q22/5*60000 -> 42600
A23: FIN | B23: 13 | C23: Wong Siew Hua | D23: Assistant Accounts Manager | E23: No 6, spg 40-127, Jalan SG Akar, Bandar Seri Begawan BE1918, Negara Brunei Darussalam | F23: Malaysian | G23: G8654768L | I23: 4.75 | J23: B+ | K23: 43556 | L23: 43556 | M23: =days(K23,$M$7)/-365 -> 5.0876712 | N23: =vlookup(M23,'Table for Factors'!$C$30:$D$35,2,true) -> 2 | O23: =vlookup(I23,'Table for Factors'!$C$38:$D$43,2,false) -> 4 | P23: 1 | Q23: =SUMPRODUCT(N23:P23,$N$9:$P$9) -> 2.95 | R23: =Q23/$Q$9 -> 0.038261997 | S23: =R23*$S$9 -> 45914.397 | U23: =Q23/5*60000 -> 35400
A24: FIN | B24: 14 | C24: Kan Siew Weng | D24: Senior Finance Executive | E24: No.18, Tingkat Melur 5, Bagan Jermal, 12300, Butterworth, Pulau Pinang | F24: Malaysian | G24: 951201065817 | I24: 4.75 | J24: B+ | K24: 43578 | L24: 43578 | M24: =days(K24,$M$7)/-365 -> 5.0273973 | N24: =vlookup(M24,'Table for Factors'!$C$30:$D$35,2,true) -> 2 | O24: =vlookup(I24,'Table for Factors'!$C$38:$D$43,2,false) -> 4 | P24: 1 | Q24: =SUMPRODUCT(N24:P24,$N$9:$P$9) -> 2.95 | R24: =Q24/$Q$9 -> 0.038261997 | S24: =R24*$S$9 -> 45914.397 | U24: =Q24/5*60000 -> 35400
A25: DHC | B25: 15 | C25: How Hee Chek (Jaysen) | D25: Senior Head of Sales | E25: 245 Hougang St 22 #13-143 S(530245) | F25: Singaporean | G25: S8000770A | I25: 4.5 | K25: 43770 | L25: 43770 | M25: =days(K25,$M$7)/-365 -> 4.5013699 | N25: =vlookup(M25,'Table for Factors'!$C$30:$D$35,2,true) -> 2 | O25: =vlookup(I25,'Table for Factors'!$C$38:$D$43,2,false) -> 3 | P25: 1 | Q25: =SUMPRODUCT(N25:P25,$N$9:$P$9) -> 2.35 | R25: =Q25/$Q$9 -> 0.030479896 | S25: =R25*$S$9 -> 36575.875 | U25: =Q25/5*60000 -> 28200
A26: DHC | B26: 16 | C26: Lim Runting | D26: Principal Consultant | E26: 226B Sumang Lane #15-220 S(822226) | F26: Singaporean | G26: S9145484Z | I26: 4.5 | K26: 41596 | L26: 41596 | M26: =days(K26,$M$7)/-365 -> 10.457534 | N26: =vlookup(M26,'Table for Factors'!$C$30:$D$35,2,true) -> 4 | O26: =vlookup(I26,'Table for Factors'!$C$38:$D$43,2,false) -> 3 | P26: 1 | Q26: =SUMPRODUCT(N26:P26,$N$9:$P$9) -> 2.65 | R26: =Q26/$Q$9 -> 0.034370947 | S26: =R26*$S$9 -> 41245.136 | U26: =Q26/5*60000 -> 31800
A27: DHC | B27: 17 | C27: Ho Si Cong | D27: Manager | E27: 233 Bain Street #13-07 S(180233) | F27: Singaporean | G27: S9419440G | I27: 4.5 | K27: 43570 | L27: 43570 | M27: =days(K27,$M$7)/-365 -> 5.0493151 | N27: =vlookup(M27,'Table for Factors'!$C$30:$D$35,2,true) -> 2 | O27: =vlookup(I27,'Table for Factors'!$C$38:$D$43,2,false) -> 3 | P27: 2 | Q27: =SUMPRODUCT(N27:P27,$N$9:$P$9) -> 2.6 | R27: =Q27/$Q$9 -> 0.033722438 | S27: =R27*$S$9 -> 40466.926 | U27: =Q27/5*60000 -> 31200
A28: DHC | B28: 18 | C28: Tiong Kai Yuen, Noreen | D28: Senior Researcher | E28: 243 Yishun Ring Road #10-1137 S(760243) | F28: Singaporean | G28: S7941127B | I28: 4 | K28: 42814 | L28: 42814 | M28: =days(K28,$M$7)/-365 -> 7.1205479 | N28: =vlookup(M28,'Table for Factors'!$C$30:$D$35,2,true) -> 3 | O28: =vlookup(I28,'Table for Factors'!$C$38:$D$43,2,false) -> 2 | P28: 1 | Q28: =SUMPRODUCT(N28:P28,$N$9:$P$9) -> 1.9 | R28: =Q28/$Q$9 -> 0.02464332 | S28: =R28*$S$9 -> 29571.984 | U28: =Q28/5*60000 -> 22800
A29: DHC | B29: 19 | C29: Tan Hui Qing | D29: Operations Manager | E29: 434B Fernvale Road #05-240 S(792434) | F29: Singaporean | G29: S8341958Z | I29: 4.5 | K29: 42065 | L29: 42065 | M29: =days(K29,$M$7)/-365 -> 9.1726027 | N29: =vlookup(M29,'Table for Factors'!$C$30:$D$35,2,true) -> 4 | O29: =vlookup(I29,'Table for Factors'!$C$38:$D$43,2,false) -> 3 | P29: 1 | Q29: =SUMPRODUCT(N29:P29,$N$9:$P$9) -> 2.65 | R29: =Q29/$Q$9 -> 0.034370947 | S29: =R29*$S$9 -> 41245.136 | U29: =Q29/5*60000 -> 31800
A30: OPS | B30: 20 | C30: Kenneth Koh | D30: Operations Manager | E30: 120D Canberra Crescent #02-403 S(754120) | F30: Singaporean | G30: S9627246D | I30: 4.75 | J30: B+ | K30: 43600 | L30: 43600 | M30: =days(K30,$M$7)/-365 -> 4.9671233 | N30: =vlookup(M30,'Table for Factors'!$C$30:$D$35,2,true) -> 2 | O30: =vlookup(I30,'Table for Factors'!$C$38:$D$43,2,false) -> 4 | P30: 1 | Q30: =SUMPRODUCT(N30:P30,$N$9:$P$9) -> 2.95 | R30: =Q30/$Q$9 -> 0.038261997 | S30: =R30*$S$9 -> 45914.397 | U30: =Q30/5*60000 -> 35400
A31: SALES | B31: 21 | C31: Heng Zeng Yang Ian | D31: Business Development Manager | E31: 158 Yung Loh Road #07-52 #07-52 S(610158) | F31: Singaporean | G31: S9114974E | I31: 5 | J31: A | K31: 43717 | L31: 43717 | M31: =days(K31,$M$7)/-365 -> 4.6465753 | N31: =vlookup(M31,'Table for Factors'!$C$30:$D$35,2,true) -> 2 | O31: =vlookup(I31,'Table for Factors'!$C$38:$D$43,2,false) -> 5 | P31: 3 | Q31: =SUMPRODUCT(N31:P31,$N$9:$P$9) -> 4.05 | R31: =Q31/$Q$9 -> 0.052529183 | S31: =R31*$S$9 -> 63035.019 | U31: =Q31/5*60000 -> 48600
A32: SALES | B32: 22 | C32: Tsai Pei-Hua (Penny) | D32: Manager | E32: 731 Tampines Street 71 #10-135 S(520731) | F32: Taiwanese | G32: S8663445G | I32: 4.5 | J32: B | K32: 43773 | L32: 43773 | M32: =days(K32,$M$7)/-365 -> 4.4931507 | N32: =vlookup(M32,'Table for Factors'!$C$30:$D$35,2,true) -> 2 | O32: =vlookup(I32,'Table for Factors'!$C$38:$D$43,2,false) -> 3 | P32: 1 | Q32: =SUMPRODUCT(N32:P32,$N$9:$P$9) -> 2.35 | R32: =Q32/$Q$9 -> 0.030479896 | S32: =R32*$S$9 -> 36575.875 | U32: =Q32/5*60000 -> 28200 | AG32: Factor 1: Years | AJ32: Factor 2 :Current Year Performance | AM32: Factor 3 :Current Year Performance
A33: SALES | B33: 23 | C33: Jorena Tan Chee Huan | D33: Business Development Manager | E33: 126C Kim Tian Rd #40-519 S(163126) | F33: Singaporean | G33: S9324775B | I33: 5 | J33: A | K33: 44088 | L33: 44088 | M33: =days(K33,$M$7)/-365 -> 3.630137 | N33: =vlookup(M33,'Table for Factors'!$C$30:$D$35,2,true) -> 1 | O33: =vlookup(I33,'Table for Factors'!$C$38:$D$43,2,false) -> 5 | P33: 2 | Q33: =SUMPRODUCT(N33:P33,$N$9:$P$9) -> 3.65 | R33: =Q33/$Q$9 -> 0.047341115 | S33: =R33*$S$9 -> 56809.339 | U33: =Q33/5*60000 -> 43800 | AG33: Points | AH33: Years | AJ33: Points | AK33: Scoring | AM33: Points | AN33: Potential
A34: SALES | B34: 24 | C34: Melissa Tan Yi Xuan | D34: Business Development Executive | E34: 315 Serangoon Avenue 2 #08-206 S(550315) | F34: Singaporean | G34: S9347251I | I34: 4.75 | J34: B+ | K34: 44308 | L34: 44308 | M34: =days(K34,$M$7)/-365 -> 3.0273973 | N34: =vlookup(M34,'Table for Factors'!$C$30:$D$35,2,true) -> 1 | O34: =vlookup(I34,'Table for Factors'!$C$38:$D$43,2,false) -> 4 | P34: 1 | Q34: =SUMPRODUCT(N34:P34,$N$9:$P$9) -> 2.8 | R34: =Q34/$Q$9 -> 0.036316472 | S34: =R34*$S$9 -> 43579.767 | U34: =Q34/5*60000 -> 33600 | AG34: 1 | AH34: 3 | AJ34: 1 | AK34: 3.5 | AM34: 1
AG35: 2 | AH35: 5 | AJ35: 2 | AK35: 4 | AM35: 2
H36: Total | P36: Total | Q36: =sum(Q11:Q34) -> 77.1 | R36: =sum(R11:R34) -> 1 | S36: =sum(S11:S34) -> 1200000 | U36: =sum(U11:U34) -> 925200

Sheet Final 2025 (Draft)
L1: Weightage
T2: Total Shares to be given (20%) | V2: 6000000
C3: Factor 1 | K3: Years in Company | L3: 0.15 | T3: Balance before FY 2025 | V3: =V2-'Consol List ESOP Given'!D11-'Consol List ESOP Given'!F11 -> 4434000 | W3: =V3/V2 -> 0.739 | AA3: Top 20% count | AB3: =PERCENTILE(Z11:Z39,0.2) -> 6
C4: Factor 2 | K4: Current Year Performance | L4: 0.6 | T4: Balance after FY 2025 | V4: =V3-S9 -> 3234000 | W4: =V4/V2 -> 0.539
C5: Factor 3 | K5: Leadership Potential | L5: 0.25 | T5: Years left if use current scheme | V5: =V3/S9-1 -> 2.695 | X5: Base proportion | Y5: =Y6/Y42 -> 0.7 | Z5: 0.7
T6: Years left (if use Derrick suggestion 2) | V6: =V3/Y41-1 -> 7.2832057 | X6: Base shares | Y6: =Y42*Z5 -> 15000 | Z6: Top 20% ESOP | AA6: =SUMIF(Z11:Z39,"<7",Y11:Y39) -> 256000 | AB6: =AA6/Y$41 -> 0.4782365
L7: Ending dates | M7: 45778 | X7: Power multiplier | Y7: 2.2978027 | Z7: Bottom 50% | AA7: =SUMIF(Z11:Z39,">14",Y11:Y39) -> 121800 | AB7: =AA7/Y$41 -> 0.22753596
M8: Scale of | N8: 0 to 5 | Q8: Total | S8: Total Shares for EGPL 2025 | X8: Rounding | Y8: -2
M9: Weightage | N9: 0.15 | O9: 0.6 | P9: 0.25 | Q9: =sum(Q11:Q39) -> 77.6 | S9: 1200000 | V9: =V41 -> 598100 | W9: =X41 -> -62800 | X9: Total | Y9: =Y41 -> 535300
A10: Department | B10: Reference Employee Pool | C10: Name | D10: Job Title | E10: Address | F10: Nationality | G10: Identity No | H10: Direct Supervisor | I10: Formatted Grading | J10: Grading for FY 2025 | K10: Formatted Joined Date | L10: Joined Date | M10: Years in Company(as of 1 May 2025) | N10: Factor 1 | O10: Factor 2 | P10: Factor 3 | Q10: Total Score | R10: Percentage | S10: 2025 ESOP Given | T10: Derrick proposal 1, using max cap 60000 | U10: Derrick proposal 2, using ½ median payout of 2023/2024 and benchmark the median scorer of 2025 | V10: Proposal 3A; If use moving forward recommendation in below box, Linear Formula | X10: Difference | Y10: Proposal 3B, Using Quadratic Formula | Z10: Rank | AC10: Derrick comments, 13 september 2025
A11: HR | B11: 1 | C11: Tok Meiting | D11: HR Manager | E11: 653C Punggol Drive #13-80 S (823653) | F11: Singaporean | G11: S9408267F | H11: W | K11: 42058 | L11: 42058 | M11: =days(K11,$M$7)/-365 -> 10.191781 | N11: =vlookup(M11,'Table for Factors'!$C$30:$D$35,2,true) -> 4 | O11: 4 | P11: 4 | Q11: =SUMPRODUCT(N11:P11,$N$9:$P$9) -> 4 | R11: =Q11/$Q$9 -> 0.051546392 | S11: =R11*$S$9 -> 61855.67 | T11: =Q11/5*60000 -> 48000 | U11: =roundup(Q11/Q$41*23000,0) -> 35385 | V11: =roundup(Q11/Q$41*20000,Y$8) -> 30800 | X11: =Y11-V11 -> 9600 | Y11: =ROUND((Q11/Q$41)^Y$7*Y$6,Y$8) -> 40400 | Z11: =RANK(Q11,Q$11:Q$39,0) -> 2
A12: FIN | B12: 2 | C12: Li Qian | D12: Senior Finance Manager | E12: 129 Ang Mo Kio Avenue 3 #11-1549 S(560129) | F12: Singaporean | G12: S9077139F | H12: R | K12: 42060 | L12: 42060 | M12: =days(K12,$M$7)/-365 -> 10.186301 | N12: =vlookup(M12,'Table for Factors'!$C$30:$D$35,2,true) -> 4 | O12: 4 | P12: 4 | Q12: =SUMPRODUCT(N12:P12,$N$9:$P$9) -> 4 | R12: =Q12/$Q$9 -> 0.051546392 | S12: =R12*$S$9 -> 61855.67 | T12: =Q12/5*60000 -> 48000 | U12: =roundup(Q12/Q$41*23000,0) -> 35385 | V12: =roundup(Q12/Q$41*20000,Y$8) -> 30800 | X12: =Y12-V12 -> 9600 | Y12: =ROUND((Q12/Q$41)^Y$7*Y$6,Y$8) -> 40400 | Z12: =RANK(Q12,Q$11:Q$39,0) -> 2 | AC12: Sustained method for future ESOP
A13: SALES | B13: 3 | C13: Eevann Seah | D13: Senior Manager | E13: 128A Canberra Street #11-508 S(751128) | F13: Singaporean | G13: S9038620D | H13: D | K13: 43283 | L13: 43283 | M13: =days(K13,$M$7)/-365 -> 6.8356164 | N13: =vlookup(M13,'Table for Factors'!$C$30:$D$35,2,true) -> 2 | O13: 4 | P13: 5 | Q13: =SUMPRODUCT(N13:P13,$N$9:$P$9) -> 3.95 | R13: =Q13/$Q$9 -> 0.050902062 | S13: =R13*$S$9 -> 61082.474 | T13: =Q13/5*60000 -> 47400 | U13: =roundup(Q13/Q$41*23000,0) -> 34943 | V13: =roundup(Q13/Q$41*20000,Y$8) -> 30400 | X13: =Y13-V13 -> 8800 | Y13: =ROUND((Q13/Q$41)^Y$7*Y$6,Y$8) -> 39200 | Z13: =RANK(Q13,Q$11:Q$39,0) -> 4 | AC13: 1 | AD13: ESOP per year cap at 600000
A14: SALES | B14: 4 | C14: Wang Jiemin (Jack) | D14: Associate Director | E14: 522B Tampines Central 7 #03-15 S(522522) | F14: Singaporean | G14: S8818978G | H14: D | K14: 42681 | L14: 42681 | M14: =days(K14,$M$7)/-365 -> 8.4849315 | N14: =vlookup(M14,'Table for Factors'!$C$30:$D$35,2,true) -> 3 | O14: 4 | P14: 5 | Q14: =SUMPRODUCT(N14:P14,$N$9:$P$9) -> 4.1 | R14: =Q14/$Q$9 -> 0.052835052 | S14: =R14*$S$9 -> 63402.062 | T14: =Q14/5*60000 -> 49200 | U14: =roundup(Q14/Q$41*23000,0) -> 36270 | V14: =roundup(Q14/Q$41*20000,Y$8) -> 31600 | X14: =Y14-V14 -> 11100 | Y14: =ROUND((Q14/Q$41)^Y$7*Y$6,Y$8) -> 42700 | Z14: =RANK(Q14,Q$11:Q$39,0) -> 1 | AC14: 2 | AD14: Base share per person = (600k / # pax) x 0.8 = share given to median performer
A15: SALES | B15: 5 | C15: Sharon Lau Jie Joo | D15: Senior Manager | E15: 353B Anchorvale Labe #14-83 S(542353) | F15: Singaporean | G15: S9349763E | H15: D | K15: 42979 | L15: 42979 | M15: =days(K15,$M$7)/-365 -> 7.6684932 | N15: =vlookup(M15,'Table for Factors'!$C$30:$D$35,2,true) -> 3 | O15: 2 | P15: 2 | Q15: =SUMPRODUCT(N15:P15,$N$9:$P$9) -> 2.15 | R15: =Q15/$Q$9 -> 0.027706186 | S15: =R15*$S$9 -> 33247.423 | T15: =Q15/5*60000 -> 25800 | U15: =roundup(Q15/Q$41*23000,0) -> 19020 | V15: =roundup(Q15/Q$41*20000,Y$8) -> 16600 | X15: =Y15-V15 -> -6900 | Y15: =ROUND((Q15/Q$41)^Y$7*Y$6,Y$8) -> 9700 | Z15: =RANK(Q15,Q$11:Q$39,0) -> 24 | AC15: 3 | AD15: Denominator = median performer. Numerator = respective individual.
A16: OPS | B16: 6 | C16: Yeoh Ser How | D16: Operations Manager | E16: 432B Northshore Drive #22-862 S(822432) | F16: Malaysian | G16: S8876646F | H16: D | K16: 42626 | L16: 42626 | M16: =days(K16,$M$7)/-365 -> 8.6356164 | N16: =vlookup(M16,'Table for Factors'!$C$30:$D$35,2,true) -> 3 | O16: 2 | P16: 2 | Q16: =SUMPRODUCT(N16:P16,$N$9:$P$9) -> 2.15 | R16: =Q16/$Q$9 -> 0.027706186 | S16: =R16*$S$9 -> 33247.423 | T16: =Q16/5*60000 -> 25800 | U16: =roundup(Q16/Q$41*23000,0) -> 19020 | V16: =roundup(Q16/Q$41*20000,Y$8) -> 16600 | X16: =Y16-V16 -> -6900 | Y16: =ROUND((Q16/Q$41)^Y$7*Y$6,Y$8) -> 9700 | Z16: =RANK(Q16,Q$11:Q$39,0) -> 24 | AC16: 4 | AD16: Power multiplier; x = approx 1.8-2.5. Use recursive (goal-seek) formula.
A17: SALES | B17: 7 | C17: Chan Wai Seng, Nicholas | D17: Head of Tenders | E17: 31 Lentor Terrace S(788926) | F17: Singaporean | G17: S9220162G | H17: D | K17: 43769 | L17: 43769 | M17: =days(K17,$M$7)/-365 -> 5.5041096 | N17: =vlookup(M17,'Table for Factors'!$C$30:$D$35,2,true) -> 2 | O17: 3 | P17: 3 | Q17: =SUMPRODUCT(N17:P17,$N$9:$P$9) -> 2.85 | R17: =Q17/$Q$9 -> 0.036726804 | S17: =R17*$S$9 -> 44072.165 | T17: =Q17/5*60000 -> 34200 | U17: =roundup(Q17/Q$41*23000,0) -> 25212 | V17: =roundup(Q17/Q$41*20000,Y$8) -> 22000 | X17: =Y17-V17 -> -3500 | Y17: =ROUND((Q17/Q$41)^Y$7*Y$6,Y$8) -> 18500 | Z17: =RANK(Q17,Q$11:Q$39,0) -> 10 | AC17: 5 | AD17: Desired st-dev should be around 10000-15000. If not, we may review the formula.
A18: SALES | B18: 8 | C18: Damien Tan Han Kiap | D18: Business Development Manager | E18: 653C Punggol Drive #13-80 S (823653) | F18: Singaporean | G18: S9405253Z | H18: R | K18: 43009 | L18: 43009 | M18: =days(K18,$M$7)/-365 -> 7.5863014 | N18: =vlookup(M18,'Table for Factors'!$C$30:$D$35,2,true) -> 3 | O18: 3 | P18: 2 | Q18: =SUMPRODUCT(N18:P18,$N$9:$P$9) -> 2.75 | R18: =Q18/$Q$9 -> 0.035438144 | S18: =R18*$S$9 -> 42525.773 | T18: =Q18/5*60000 -> 33000 | U18: =roundup(Q18/Q$41*23000,0) -> 24327 | V18: =roundup(Q18/Q$41*20000,Y$8) -> 21200 | X18: =Y18-V18 -> -4100 | Y18: =ROUND((Q18/Q$41)^Y$7*Y$6,Y$8) -> 17100 | Z18: =RANK(Q18,Q$11:Q$39,0) -> 12 | AC18: 6 | AD18: Top 20% ESOP holders should take 38-50%. If out of this range, review the formula.
A19: FIN | B19: 9 | C19: Chen Ting | D19: Senior Finance Executive | E19: 45 Bendemeer Road, #06-1439 S(330045) | F19: Chinese | G19: S9374645G | H19: R | K19: 42499 | L19: 42499 | M19: =days(K19,$M$7)/-365 -> 8.9835616 | N19: =vlookup(M19,'Table for Factors'!$C$30:$D$35,2,true) -> 3 | O19: 3 | P19: 1 | Q19: =SUMPRODUCT(N19:P19,$N$9:$P$9) -> 2.5 | R19: =Q19/$Q$9 -> 0.032216495 | S19: =R19*$S$9 -> 38659.794 | T19: =Q19/5*60000 -> 30000 | U19: =roundup(Q19/Q$41*23000,0) -> 22116 | V19: =roundup(Q19/Q$41*20000,Y$8) -> 19300 | X19: =Y19-V19 -> -5600 | Y19: =ROUND((Q19/Q$41)^Y$7*Y$6,Y$8) -> 13700 | Z19: =RANK(Q19,Q$11:Q$39,0) -> 17 | AC19: 7 | AD19: Rounding to nearest hundred
A20: OPS | B20: 10 | C20: Andy Lim Wen Jie | D20: Deputy Head, ESG | E20: 121B Edgedale Plains #06-193 S(822121) | F20: Singaporean | G20: S9436300D | H20: D | K20: 43339 | L20: 43339 | M20: =days(K20,$M$7)/-365 -> 6.6821918 | N20: =vlookup(M20,'Table for Factors'!$C$30:$D$35,2,true) -> 2 | O20: 3 | P20: 2 | Q20: =SUMPRODUCT(N20:P20,$N$9:$P$9) -> 2.6 | R20: =Q20/$Q$9 -> 0.033505155 | S20: =R20*$S$9 -> 40206.186 | T20: =Q20/5*60000 -> 31200 | U20: =roundup(Q20/Q$41*23000,0) -> 23000 | V20: =roundup(Q20/Q$41*20000,Y$8) -> 20000 | X20: =Y20-V20 -> -5000 | Y20: =ROUND((Q20/Q$41)^Y$7*Y$6,Y$8) -> 15000 | Z20: =RANK(Q20,Q$11:Q$39,0) -> 13
A21: HR | B21: 11 | C21: Aiydon Li Yi Xuan | D21: Team Lead | E21: 224B Sumang Lane #13-119 S(822224) | F21: Singaporean | G21: S8781890Z | H21: W | K21: 43011 | L21: 43011 | M21: =days(K21,$M$7)/-365 -> 7.5808219 | N21: =vlookup(M21,'Table for Factors'!$C$30:$D$35,2,true) -> 3 | O21: 3 | P21: 1 | Q21: =SUMPRODUCT(N21:P21,$N$9:$P$9) -> 2.5 | R21: =Q21/$Q$9 -> 0.032216495 | S21: =R21*$S$9 -> 38659.794 | T21: =Q21/5*60000 -> 30000 | U21: =roundup(Q21/Q$41*23000,0) -> 22116 | V21: =roundup(Q21/Q$41*20000,Y$8) -> 19300 | X21: =Y21-V21 -> -5600 | Y21: =ROUND((Q21/Q$41)^Y$7*Y$6,Y$8) -> 13700 | Z21: =RANK(Q21,Q$11:Q$39,0) -> 17 | AC21: Adjustment to IPO announcement
A22: FIN | B22: 12 | C22: Wong Siew Hua | D22: Assistant Accounts Manager | E22: No 6, spg 40-127, Jalan SG Akar, Bandar Seri Begawan BE1918, Negara Brunei Darussalam | F22: Malaysian | G22: G8654768L | H22: R | K22: 43556 | L22: 43556 | M22: =days(K22,$M$7)/-365 -> 6.0876712 | N22: =vlookup(M22,'Table for Factors'!$C$30:$D$35,2,true) -> 2 | O22: 4 | P22: 3 | Q22: =SUMPRODUCT(N22:P22,$N$9:$P$9) -> 3.45 | R22: =Q22/$Q$9 -> 0.044458763 | S22: =R22*$S$9 -> 53350.515 | T22: =Q22/5*60000 -> 41400 | U22: =roundup(Q22/Q$41*23000,0) -> 30520 | V22: =roundup(Q22/Q$41*20000,Y$8) -> 26600 | X22: =Y22-V22 -> 2100 | Y22: =ROUND((Q22/Q$41)^Y$7*Y$6,Y$8) -> 28700 | Z22: =RANK(Q22,Q$11:Q$39,0) -> 6 | AC22: 1 | AD22: Not listing by 2027, due to broader environment and lack of liquidity in market. Modify narrative.
A23: FIN | B23: 13 | C23: Kan Siew Weng | D23: Senior Finance Executive | E23: No.18, Tingkat Melur 5, Bagan Jermal, 12300, Butterworth, Pulau Pinang | F23: Malaysian | G23: 951201065817 | H23: R | K23: 43578 | L23: 43578 | M23: =days(K23,$M$7)/-365 -> 6.0273973 | N23: =vlookup(M23,'Table for Factors'!$C$30:$D$35,2,true) -> 2 | O23: 3 | P23: 2 | Q23: =SUMPRODUCT(N23:P23,$N$9:$P$9) -> 2.6 | R23: =Q23/$Q$9 -> 0.033505155 | S23: =R23*$S$9 -> 40206.186 | T23: =Q23/5*60000 -> 31200 | U23: =roundup(Q23/Q$41*23000,0) -> 23000 | V23: =roundup(Q23/Q$41*20000,Y$8) -> 20000 | X23: =Y23-V23 -> -5000 | Y23: =ROUND((Q23/Q$41)^Y$7*Y$6,Y$8) -> 15000 | Z23: =RANK(Q23,Q$11:Q$39,0) -> 13 | AC23: 2 | AD23: Example; we can still M&A and acquire assets through our company funding mechanism (internal and external).
A24: DHC | B24: 14 | C24: How Hee Chek (Jaysen) | D24: Deputy Regional Head of Sales | E24: 245 Hougang St 22 #13-143 S(530245) | F24: Singaporean | G24: S8000770A | H24: Y | K24: 43770 | L24: 43770 | M24: =days(K24,$M$7)/-365 -> 5.5013699 | N24: =vlookup(M24,'Table for Factors'!$C$30:$D$35,2,true) -> 2 | O24: 3 | P24: 2 | Q24: =SUMPRODUCT(N24:P24,$N$9:$P$9) -> 2.6 | R24: =Q24/$Q$9 -> 0.033505155 | S24: =R24*$S$9 -> 40206.186 | T24: =Q24/5*60000 -> 31200 | U24: =roundup(Q24/Q$41*23000,0) -> 23000 | V24: =roundup(Q24/Q$41*20000,Y$8) -> 20000 | X24: =Y24-V24 -> -5000 | Y24: =ROUND((Q24/Q$41)^Y$7*Y$6,Y$8) -> 15000 | Z24: =RANK(Q24,Q$11:Q$39,0) -> 13 | AC24: 3 | AD24: As such, we will allow earlier vesting by 1 year -> 2022's 400k can vest in May 2026 instead of 2027.
A25: DHC | B25: 15 | C25: Lim Runting | D25: Principal Consultant | E25: 226B Sumang Lane #15-220 S(822226) | F25: Singaporean | G25: S9145484Z | H25: Y | K25: 41596 | L25: 41596 | M25: =days(K25,$M$7)/-365 -> 11.457534 | N25: =vlookup(M25,'Table for Factors'!$C$30:$D$35,2,true) -> 4 | O25: 2 | P25: 2 | Q25: =SUMPRODUCT(N25:P25,$N$9:$P$9) -> 2.3 | R25: =Q25/$Q$9 -> 0.029639175 | S25: =R25*$S$9 -> 35567.01 | T25: =Q25/5*60000 -> 27600 | U25: =roundup(Q25/Q$41*23000,0) -> 20347 | V25: =roundup(Q25/Q$41*20000,Y$8) -> 17700 | X25: =Y25-V25 -> -6400 | Y25: =ROUND((Q25/Q$41)^Y$7*Y$6,Y$8) -> 11300 | Z25: =RANK(Q25,Q$11:Q$39,0) -> 22 | AI25: Illustration | AJ25: Discount factor | AK25: 0.75
A26: DHC | B26: 16 | C26: Ho Si Cong | D26: Manager | E26: 233 Bain Street #13-07 S(180233) | F26: Singaporean | G26: S9419440G | H26: Y | K26: 43570 | L26: 43570 | M26: =days(K26,$M$7)/-365 -> 6.0493151 | N26: =vlookup(M26,'Table for Factors'!$C$30:$D$35,2,true) -> 2 | O26: 2 | P26: 2 | Q26: =SUMPRODUCT(N26:P26,$N$9:$P$9) -> 2 | R26: =Q26/$Q$9 -> 0.025773196 | S26: =R26*$S$9 -> 30927.835 | T26: =Q26/5*60000 -> 24000 | U26: =roundup(Q26/Q$41*23000,0) -> 17693 | V26: =roundup(Q26/Q$41*20000,Y$8) -> 15400 | X26: =Y26-V26 -> -7200 | Y26: =ROUND((Q26/Q$41)^Y$7*Y$6,Y$8) -> 8200 | Z26: =RANK(Q26,Q$11:Q$39,0) -> 26 | AC26: How to vest? | AJ26: Options converted; | AK26: 100000
A27: DHC | B27: 17 | C27: Tiong Kai Yuen, Noreen | D27: Senior Researcher | E27: 243 Yishun Ring Road #10-1137 S(760243) | F27: Singaporean | G27: S7941127B | H27: Y | K27: 42814 | L27: 42814 | M27: =days(K27,$M$7)/-365 -> 8.1205479 | N27: =vlookup(M27,'Table for Factors'!$C$30:$D$35,2,true) -> 3 | O27: 2 | P27: 1 | Q27: =SUMPRODUCT(N27:P27,$N$9:$P$9) -> 1.9 | R27: =Q27/$Q$9 -> 0.024484536 | S27: =R27*$S$9 -> 29381.443 | T27: =Q27/5*60000 -> 22800 | U27: =roundup(Q27/Q$41*23000,0) -> 16808 | V27: =roundup(Q27/Q$41*20000,Y$8) -> 14700 | X27: =Y27-V27 -> -7400 | Y27: =ROUND((Q27/Q$41)^Y$7*Y$6,Y$8) -> 7300 | Z27: =RANK(Q27,Q$11:Q$39,0) -> 27 | AC27: 46082 | AD27: Encourage all 2022 vestees to pay 10% on May 2026. | AI27: 1 | AJ27: Paid cash to convert; | AK27: =AK26*0.1*AI27 -> 10000
A28: DHC | B28: 18 | C28: Tan Hui Qing | D28: Operations Manager | E28: 434B Fernvale Road #05-240 S(792434) | F28: Singaporean | G28: S8341958Z | H28: Y | K28: 42065 | L28: 42065 | M28: =days(K28,$M$7)/-365 -> 10.172603 | N28: =vlookup(M28,'Table for Factors'!$C$30:$D$35,2,true) -> 4 | O28: 3 | P28: 3 | Q28: =SUMPRODUCT(N28:P28,$N$9:$P$9) -> 3.15 | R28: =Q28/$Q$9 -> 0.040592784 | S28: =R28*$S$9 -> 48711.34 | T28: =Q28/5*60000 -> 37800 | U28: =roundup(Q28/Q$41*23000,0) -> 27866 | V28: =roundup(Q28/Q$41*20000,Y$8) -> 24300 | X28: =Y28-V28 -> -1000 | Y28: =ROUND((Q28/Q$41)^Y$7*Y$6,Y$8) -> 23300 | Z28: =RANK(Q28,Q$11:Q$39,0) -> 8 | AC28: 46174 | AD28: Allow each shareholder to sell up to 10%/yr of their current holdings at 60% discount. | AI28: 0.2 | AJ28: Sell at discount; | AK28: =AI28*AK26*(1-AK25)*AI27 -> 5000
A29: OPS | B29: 19 | C29: Kenneth Koh | D29: Operations Manager | E29: 120D Canberra Crescent #02-403 S(754120) | F29: Singaporean | G29: S9627246D | H29: D | K29: 43600 | L29: 43600 | M29: =days(K29,$M$7)/-365 -> 5.9671233 | N29: =vlookup(M29,'Table for Factors'!$C$30:$D$35,2,true) -> 2 | O29: 1 | P29: 1 | Q29: =SUMPRODUCT(N29:P29,$N$9:$P$9) -> 1.15 | R29: =Q29/$Q$9 -> 0.014819588 | S29: =R29*$S$9 -> 17783.505 | T29: =Q29/5*60000 -> 13800 | U29: =roundup(Q29/Q$41*23000,0) -> 10174 | V29: =roundup(Q29/Q$41*20000,Y$8) -> 8900 | X29: =Y29-V29 -> -6600 | Y29: =ROUND((Q29/Q$41)^Y$7*Y$6,Y$8) -> 2300 | Z29: =RANK(Q29,Q$11:Q$39,0) -> 28 | AC29: 46266 | AD29: Declare dividend, approx $0.03 per share. | AI29: 0.03 | AJ29: Receive dividend; | AK29: =AK26*(1-AI28)*AI29 -> 2400
A30: SALES | B30: 20 | C30: Heng Zeng Yang Ian | D30: Business Development Manager | E30: 158 Yung Loh Road #07-52 #07-52 S(610158) | F30: Singaporean | G30: S9114974E | H30: D | K30: 43717 | L30: 43717 | M30: =days(K30,$M$7)/-365 -> 5.6465753 | N30: =vlookup(M30,'Table for Factors'!$C$30:$D$35,2,true) -> 2 | O30: 3 | P30: 3 | Q30: =SUMPRODUCT(N30:P30,$N$9:$P$9) -> 2.85 | R30: =Q30/$Q$9 -> 0.036726804 | S30: =R30*$S$9 -> 44072.165 | T30: =Q30/5*60000 -> 34200 | U30: =roundup(Q30/Q$41*23000,0) -> 25212 | V30: =roundup(Q30/Q$41*20000,Y$8) -> 22000 | X30: =Y30-V30 -> -3500 | Y30: =ROUND((Q30/Q$41)^Y$7*Y$6,Y$8) -> 18500 | Z30: =RANK(Q30,Q$11:Q$39,0) -> 10 | AJ30: Net paid (perceived); | AK30: =AK27-AK28-AK29 -> 2600
A31: SALES | B31: 21 | C31: Tsai Pei-Hua (Penny) | D31: Manager | E31: 731 Tampines Street 71 #10-135 S(520731) | F31: Taiwanese | G31: S8663445G | H31: D | K31: 43773 | L31: 43773 | M31: =days(K31,$M$7)/-365 -> 5.4931507 | N31: =vlookup(M31,'Table for Factors'!$C$30:$D$35,2,true) -> 2 | O31: 3 | P31: 1 | Q31: =SUMPRODUCT(N31:P31,$N$9:$P$9) -> 2.35 | R31: =Q31/$Q$9 -> 0.030283505 | S31: =R31*$S$9 -> 36340.206 | T31: =Q31/5*60000 -> 28200 | U31: =roundup(Q31/Q$41*23000,0) -> 20789 | V31: =roundup(Q31/Q$41*20000,Y$8) -> 18100 | X31: =Y31-V31 -> -6200 | Y31: =ROUND((Q31/Q$41)^Y$7*Y$6,Y$8) -> 11900 | Z31: =RANK(Q31,Q$11:Q$39,0) -> 19 | AC31: Desired result? | AJ31: Share balance | AK31: =AK26*(1-AI28) -> 80000
A32: SALES | B32: 22 | C32: Jorena Tan Chee Huan | D32: Business Development Manager | E32: 126C Kim Tian Rd #40-519 S(163126) | F32: Singaporean | G32: S9324775B | H32: D | K32: 44088 | L32: 44088 | M32: =days(K32,$M$7)/-365 -> 4.630137 | N32: =vlookup(M32,'Table for Factors'!$C$30:$D$35,2,true) -> 2 | O32: 3 | P32: 1 | Q32: =SUMPRODUCT(N32:P32,$N$9:$P$9) -> 2.35 | R32: =Q32/$Q$9 -> 0.030283505 | S32: =R32*$S$9 -> 36340.206 | T32: =Q32/5*60000 -> 28200 | U32: =roundup(Q32/Q$41*23000,0) -> 20789 | V32: =roundup(Q32/Q$41*20000,Y$8) -> 18100 | X32: =Y32-V32 -> -6200 | Y32: =ROUND((Q32/Q$41)^Y$7*Y$6,Y$8) -> 11900 | Z32: =RANK(Q32,Q$11:Q$39,0) -> 19 | AC32: 1 | AD32: Upload the belief that ESOP is worth money.
A33: SALES | B33: 23 | C33: Melissa Tan Yi Xuan | D33: Senior Business Development Executive | E33: 315 Serangoon Avenue 2 #08-206 S(550315) | F33: Singaporean | G33: S9347251I | H33: D | K33: 44308 | L33: 44308 | M33: =days(K33,$M$7)/-365 -> 4.0273973 | N33: =vlookup(M33,'Table for Factors'!$C$30:$D$35,2,true) -> 2 | O33: 3 | P33: 1 | Q33: =SUMPRODUCT(N33:P33,$N$9:$P$9) -> 2.35 | R33: =Q33/$Q$9 -> 0.030283505 | S33: =R33*$S$9 -> 36340.206 | T33: =Q33/5*60000 -> 28200 | U33: =roundup(Q33/Q$41*23000,0) -> 20789 | V33: =roundup(Q33/Q$41*20000,Y$8) -> 18100 | X33: =Y33-V33 -> -6200 | Y33: =ROUND((Q33/Q$41)^Y$7*Y$6,Y$8) -> 11900 | Z33: =RANK(Q33,Q$11:Q$39,0) -> 19 | AC33: 2 | AD33: Create a tradable and liquidity mechanism for peope to increase or reduce their shareholding.
A34: FIN | B34: 24 | C34: Marilyn Choo Lih Cheen (MSIA) | D34: Team Lead | E34: 55 Tampines Central 7 #06-11 S(528617) | F34: Malaysian | G34: S9281317G | H34: R | K34: 44197 | L34: 44682 | M34: =days(K34,$M$7)/-365 -> 4.3315068 | N34: =vlookup(M34,'Table for Factors'!$C$30:$D$35,2,true) -> 2 | O34: 5 | P34: 2 | Q34: =SUMPRODUCT(N34:P34,$N$9:$P$9) -> 3.8 | R34: =Q34/$Q$9 -> 0.048969072 | S34: =R34*$S$9 -> 58762.887 | T34: =Q34/5*60000 -> 45600 | U34: =roundup(Q34/Q$41*23000,0) -> 33616 | V34: =roundup(Q34/Q$41*20000,Y$8) -> 29300 | X34: =Y34-V34 -> 6600 | Y34: =ROUND((Q34/Q$41)^Y$7*Y$6,Y$8) -> 35900 | Z34: =RANK(Q34,Q$11:Q$39,0) -> 5 | AC34: 3 | AD34: Direct signal on who could be the strong supporters of our vision (if they dont sell, and even buy).
A35: DHC | B35: 25 | C35: Phua Qiu Ru | D35: Senior Manager | E35: 286B Compassvale Crescent #06-99 S(542286) | F35: Singaporean | G35: S8700923H | H35: Y | K35: 44562 | L35: 44881 | M35: =days(K35,$M$7)/-365 -> 3.3315068 | N35: 2 | O35: 3 | P35: 2 | Q35: =SUMPRODUCT(N35:P35,$N$9:$P$9) -> 2.6 | R35: =Q35/$Q$9 -> 0.033505155 | S35: =R35*$S$9 -> 40206.186 | T35: =Q35/5*60000 -> 31200 | U35: =roundup(Q35/Q$41*23000,0) -> 23000 | V35: =roundup(Q35/Q$41*20000,Y$8) -> 20000 | X35: =Y35-V35 -> -5000 | Y35: =ROUND((Q35/Q$41)^Y$7*Y$6,Y$8) -> 15000 | Z35: =RANK(Q35,Q$11:Q$39,0) -> 13 | AC35: 4 | AD35: Exemplar for future ESOP holders to see the real value. (ideally, they are motivated to understand more how ESOP works)
A36: SALES | B36: 26 | C36: Neo Xian Yao | D36: Assistant Business Development Manager | E36: 314 Woodlands Street 31 #12-92 S(730314) | F36: Singaporean | G36: S9637999D | H36: D | K36: 44562 | L36: 44562 | M36: =days(K36,$M$7)/-365 -> 3.3315068 | N36: 2 | O36: 4 | P36: 1 | Q36: =SUMPRODUCT(N36:P36,$N$9:$P$9) -> 2.95 | R36: =Q36/$Q$9 -> 0.038015464 | S36: =R36*$S$9 -> 45618.557 | T36: =Q36/5*60000 -> 35400 | U36: =roundup(Q36/Q$41*23000,0) -> 26097 | V36: =roundup(Q36/Q$41*20000,Y$8) -> 22700 | X36: =Y36-V36 -> -2600 | Y36: =ROUND((Q36/Q$41)^Y$7*Y$6,Y$8) -> 20100 | Z36: =RANK(Q36,Q$11:Q$39,0) -> 9 | AC36: 5 | AD36: Option; we can then reduce the 90% discount for 2027-issued to 85% or 80% (if ESOP activity and excitment is high)
A37: FIN | B37: 27 | C37: Tan Sheng Yang | D37: Assistant Finance Manager | E37: 559 Hougang Street 51 #13-396 S(530559) | F37: Singaporean | G37: S9118893G | H37: R | K37: 44562 | L37: 44564 | M37: =days(K37,$M$7)/-365 -> 3.3315068 | N37: 2 | O37: 4 | P37: 3 | Q37: =SUMPRODUCT(N37:P37,$N$9:$P$9) -> 3.45 | R37: =Q37/$Q$9 -> 0.044458763 | S37: =R37*$S$9 -> 53350.515 | T37: =Q37/5*60000 -> 41400 | U37: =roundup(Q37/Q$41*23000,0) -> 30520 | V37: =roundup(Q37/Q$41*20000,Y$8) -> 26600 | X37: =Y37-V37 -> 2100 | Y37: =ROUND((Q37/Q$41)^Y$7*Y$6,Y$8) -> 28700 | Z37: =RANK(Q37,Q$11:Q$39,0) -> 6 | AC37: 6
A38: SALES | B38: 28 | C38: Chan Huan Zhang Adrian | D38: BD Manager | E38: 272C Jurong West Street 24 #11-10 S(643272) | F38: Singaporean | G38: S9442162D | H38: Y | K38: 44197 | L38: 44431 | M38: =days(K38,$M$7)/-365 -> 4.3315068 | N38: 1 | O38: 3 | P38: 1 | Q38: =SUMPRODUCT(N38:P38,$N$9:$P$9) -> 2.2 | R38: =Q38/$Q$9 -> 0.028350515 | S38: =R38*$S$9 -> 34020.619 | T38: =Q38/5*60000 -> 26400 | U38: =roundup(Q38/Q$41*23000,0) -> 19462 | V38: =roundup(Q38/Q$41*20000,Y$8) -> 17000 | X38: =Y38-V38 -> -6800 | Y38: =ROUND((Q38/Q$41)^Y$7*Y$6,Y$8) -> 10200 | Z38: =RANK(Q38,Q$11:Q$39,0) -> 23
B39: 29 | C39: Toh Hui Leong (Daryl) | D39: Senior Manager | E39: 526 Hougang Avenue 6, #10-149 S(530526) | F39: Singaporean | G39: S9048049I | H39: D | K39: 42961 | L39: 42961 | M39: =days(K39,$M$7)/-365 -> 7.7178082 | N39: 0 | O39: 0 | P39: 0
A40: =COUNTA(A11:A39) -> 28
...

Sheet Table for Factors
C29: Factor 1 | D29: Years in Company
C30: Years | D30: Points | G30: Factor 1 | H30: 1200000 | I30: PER YEAR | J30: SEOP
C31: 3 | D31: 1 | G31: Factor 2 | H31: 120000 | I31: Capped as | J31: per pax can get per year
C32: 4 | D32: 2
C33: 7 | D33: 3
C34: 9 | D34: 4
C35: 12 | D35: 5
C37: Factor 2
C38: Years | D38: Points
B39: C+ | C39: 3.5 | D39: 1
B40: B- | C40: 4 | D40: 2
B41: B | C41: 4.5 | D41: 3
B42: B+ | C42: 4.75 | D42: 4
B43: A | C43: 5 | D43: 5

Sheet Factors(View)

Sheet Trading Rules
B4: ESOP Rules
A6: 1 | B6: Valuation Of Group Shares | C6: Remarks
B7: 1.1. Suggest a PE on EBITDA , if EBITDA is negative, we will floor it at the net tangible assets (Use 4X to 6X; I propose 5X as average)
B8: 1.2 Proposed to follow the Elitez GROUP audited books for consistency. ( Will be out Yearly by 30 Nov)
A11: 2 | B11: ESOP holders exercise the option (90%) -> all Held under TRUST (under RJ, otherwise compliance cost)-> monies all goes back to the EGPL
B12: 2.1 Employee under subsi which does not hold 100%; Subsi to top up the difference for the ESOP given at group level as Group does not own the subsi 100%, MI Shareholders need to co share the cost
B13: 2.2 Employee pay 10% of the per share valued price
B14: 2.3 Employee is entitled to the Economical rights but non voting (Employee can get Dividends and liquidity event)
B15: 2.4 In an event employee leaves, company will buy back all the shares from the employees at the price they bought at ( ie 90% discount)
B17: Note 2.1
B18: The monies collected from the ESOP holders will be pump to the non-100% subsi for usage
B19: Whenever there is monies paid, Subsi need to co-share the cost based on the % of shareholding of the Minority interest
B20: For Example: FMCG; 80% group, 20% Eevann; Elitez group ESOP holder Jorena who is under FMCG FT; Whenever there is a Payout from the Group, dividends ; The Group will charge the Subsi 100% of total monies paid to these group of employees.
B21: In Event of Trade Sale or IPO; Subsi will be valued and all MI will be swap to the group at the neogotiated valuation
A23: 3 | B23: Buy and Sell
B24: 3.1 Every 1st Jan (2 weeks for submission; 2 weeks to clear); Employee can submit to buy and sell with each other at the price. ( We just use a form for them to submit) | C24: Company will have rights to buy up to 100% first
B25: 3.2 No cap or limit on the shares Employee can sell ( As it depends on the internal Market)
B26: 3.3 We allow exercise date to be Every Year March (2 weeks) ; Employee needs to hold to next Jan (9 months) before got change to "sell" (Depeding on whether got market)
A29: 4 | B29: PROPOSED to have a PROPER AGM for our Elitez Group Yearly in Jan (Only ESOP holders and Shareholders to attend)
B30: 4.1 Agenda can follow IPO companies
B33: Possible FAQ( Pls add)

Sheet Valuation
C2: Total Equity | D2: 15773353 | E2: 13841282 | F2: 8714096 | G2: 6386190 | H2: 5540254
C3: Proposed Valuation | D3: =if(D10<0,D2,D10) -> 27745614 | E3: =if(E10<0,E2,E10) -> 36881832 | F3: =if(F10<0,F2,F10) -> 13326534 | G3: =if(G10<0,G2,G10) -> 6386190 | H3: 32432432
D5: 2025 | E5: 2024 | F5: 2023 | G5: 2022 | H5: 2021
C6: EBITDA (Cashflow from Operations) | D6: 4624269 | E6: 6146972 | F6: 2221089 | G6: -690139 | H6: 2866596
C8: Mutiple | D8: 6 | E8: 6 | F8: 6 | G8: 6 | H8: 6
C10: Estimated Valuation | D10: =D6*D8 -> 27745614 | E10: =E6*E8 -> 36881832 | F10: =F6*F8 -> 13326534 | G10: =G6*G8 -> -4140834 | H10: =H6*H8 -> 17199576
C12: Total Outstanding Shares | D12: 32432432
C14: Price per share | D14: =D3/D12 -> 0.85548978 | E14: 32432432 | F14: 32432432 | G14: 32432432 | H14: =if(H10<0,H2,H10) -> 17199576
E16: =E3/E14 -> 1.1371898 | F16: =F3/F14 -> 0.41090147 | G16: =G3/G14 -> 0.19690753
H18: =H14/H3 -> 0.53032027

Sheet AA Sale
H4: Remarks
F5: Total | G5: 1400000 | H5: Lump Sum
F6: Broker Tommy Tan | G6: =G5*H6 -> 56000 | H6: 0.04 | I6: Broker Fee
F7: Set Aside for Adept Staff | G7: 30000
F9: Sub Total Balance | G9: =G5-G6-G7 -> 1314000 | H9: For Shareholders
F11: Tommy | G11: =G9*H11 -> 262800 | H11: 0.2
F12: EGPL | G12: =G9-G11 -> 1051200 | H12: 0.8 | U12: Total Amount Catered | V12: =X23 -> 70054.464
U13: Total Shares | V13: =sum(V18:V45) -> 2056942
U14: Per share Dividends | V14: =V12/V13 -> 0.034057578 | X14: 1470000
F15: ESOP Holders | G15: =G12*H15 -> 66646.08 | H15: 0.0634 | J15: =J52 -> 2056942 | K15: =G15/J15 -> 0.032400563
X16: =X14*(1-Y16) -> 1411200 | Y16: 0.04
E17: ESOP Holders | K17: Total Amount to split | L17: =G15 -> 66646.08 | P17: S/N | Q17: Name | R17: FY 2022 | S17: FY 2023 | T17: FY 2024 | U17: FY 2025 | V17: Total | X17: 30000
D18: Employee Pool | E18: Name | F18: FY 2022 | G18: FY 2023 | H18: FY 2024 | I18: FY 2025 | J18: Total | P18: 1 | Q18: Tok Meiting | R18: 60000 | T18: 71595.331 | U18: 40400 | V18: =sum(R18:U18) -> 171995.33
D19: 1 | E19: Tok Meiting | F19: 60000 | H19: 71595.331 | I19: 40400 | J19: =sum(F19:I19) -> 171995.33 | K19: =J19/$J$52 -> 0.083617005 | L19: =K19*$L$17 -> 5572.7456 | P19: 2 | Q19: Li Qian | R19: 60000 | T19: 71595.331 | U19: 40400 | V19: =sum(R19:U19) -> 171995.33 | X19: =X16-X17 -> 1381200 | Y19: Nett for shareholders
D20: 2 | E20: Li Qian | F20: 60000 | H20: 71595.331 | I20: 40400 | J20: =sum(F20:I20) -> 171995.33 | K20: =J20/$J$52 -> 0.083617005 | L20: =K20*$L$17 -> 5572.7456 | P20: 3 | Q20: Eevann Seah | R20: 35000 | T20: 66926.07 | U20: 39200 | V20: =sum(R20:U20) -> 141126.07
D21: 3 | E21: Eevann Seah | F21: 35000 | H21: 66926.07 | I21: 39200 | J21: =sum(F21:I21) -> 141126.07 | K21: =J21/$J$52 -> 0.068609649 | L21: =K21*$L$17 -> 4572.5642 | P21: 4 | Q21: Wang Jiemin (Jack) | R21: 40000 | T21: 69260.7 | U21: 42700 | V21: =sum(R21:U21) -> 151960.7 | X21: =X19*Y21 -> 1104960 | Y21: 0.8 | Z21: EGPL
D22: 4 | E22: Wang Jiemin (Jack) | F22: 40000 | H22: 69260.7 | I22: 42700 | J22: =sum(F22:I22) -> 151960.7 | K22: =J22/$J$52 -> 0.073876997 | L22: =K22*$L$17 -> 4923.6123 | P22: 5 | Q22: Sharon Lau Jie Joo | R22: 40000 | T22: 66926.07 | U22: 9700 | V22: =sum(R22:U22) -> 116626.07
D23: 5 | E23: Daryl Toh | K23: =J23/$J$52 -> 0 | L23: =K23*$L$17 -> 0 | P23: 6 | Q23: Yeoh Ser How | R23: 26000 | T23: 52140.078 | U23: 9700 | V23: =sum(R23:U23) -> 87840.078 | X23: =X21*Y23 -> 70054.464 | Y23: 0.0634 | Z23: For ESOP
D24: 6 | E24: Sharon Lau Jie Joo | F24: 40000 | H24: 66926.07 | I24: 9700 | J24: =sum(F24:I24) -> 116626.07 | K24: =J24/$J$52 -> 0.056698764 | L24: =K24*$L$17 -> 3778.7504 | P24: 7 | Q24: Chan Wai Seng, Nicholas | R24: 25000 | T24: 40466.926 | U24: 18500 | V24: =sum(R24:U24) -> 83966.926
D25: 7 | E25: Yeoh Ser How | F25: 26000 | H25: 52140.078 | I25: 9700 | J25: =sum(F25:I25) -> 87840.078 | K25: =J25/$J$52 -> 0.042704207 | L25: =K25*$L$17 -> 2846.068 | P25: 8 | Q25: Damien Tan Han Kiap | R25: 20000 | T25: 45914.397 | U25: 17100 | V25: =sum(R25:U25) -> 83014.397
D26: 8 | E26: Samion Ong | K26: =J26/$J$52 -> 0 | L26: =K26*$L$17 -> 0 | P26: 9 | Q26: Chen Ting | R26: 20000 | T26: 48249.027 | U26: 13700 | V26: =sum(R26:U26) -> 81949.027
D27: 9 | E27: Chan Wai Seng, Nicholas | F27: 25000 | H27: 40466.926 | I27: 18500 | J27: =sum(F27:I27) -> 83966.926 | K27: =J27/$J$52 -> 0.040821241 | L27: =K27*$L$17 -> 2720.5757 | P27: 10 | Q27: Andy Lim Wen Jie | R27: 20000 | T27: 40466.926 | U27: 15000 | V27: =sum(R27:U27) -> 75466.926
D28: 10 | E28: Philip Leong | K28: =J28/$J$52 -> 0 | L28: =K28*$L$17 -> 0 | P28: 11 | Q28: Aiydon Li Yi Xuan | R28: 20000 | T28: 55252.918 | U28: 13700 | V28: =sum(R28:U28) -> 88952.918
D29: 11 | E29: Asmond Soh | K29: =J29/$J$52 -> 0 | L29: =K29*$L$17 -> 0 | P29: 12 | Q29: Wong Siew Hua | R29: 0 | T29: 45914.397 | U29: 28700 | V29: =sum(R29:U29) -> 74614.397
